<?xml version="1.0"?>
<!-- Open_Manipulator Chain -->
<robot name="open_manipulator" xmlns:xacro="http://www.ros.org/wiki/xacro">

<!-- Import all Gazebo-customization elements, including Gazebo colors -->
  <!--xacro:include filename="$(find open_manipulator_support_description)/urdf/open_manipulator.gazebo.xacro"/-->
<!-- Import Rviz colors -->
  <xacro:include filename="$(find open_manipulator_support_description)/urdf/materials.xacro" />
<!-- Import inertial Properties-->
  <xacro:include filename="$(find open_manipulator_support_description)/urdf/inertial_properties.xacro" />
<!-- Import inertial Properties-->
  <xacro:include filename="$(find open_manipulator_support_description)/urdf/mass_properties.xacro" />
   
 <!-- World -->
   <link name="world">
   </link>

<!-- World fixed joint -->
   <joint name="world_fixed" type="fixed">
     <parent link="world"/>
     <child link="base_link"/>
   </joint>


<link name="base_link">
    <collision>
      <origin xyz="0 0 0.75" rpy="-3.1416 0 0"/>
      <geometry>
    <box size="0.01 0.01 0.01"/>
         <!--mesh filename="package://mrm_description/urdf/robot_arm_stl/basecone.STL" scale="0.01 0.01 0.01"/-->
      </geometry>
    </collision>

    <visual>
      <origin xyz="0 0 0.75" rpy="-3.1416 0 0"/>
      <geometry>
        <mesh filename="package://mrm_description/urdf/robot_arm_stl/basecone.STL" scale="0.01 0.01 0.01"/>
      </geometry>
    </visual>

    <inertial>
      <mass value="10" />
      <origin xyz="0 0 0.75" rpy="-3.1416 0 0"/>
      <inertia ixx="0.4" ixy="0.0" ixz="0.0" iyy="0.4" iyz="0.0" izz="0.2" />
    </inertial>
  </link>

    <joint name="joint2" type="revolute">
        <axis xyz="0 0 1" />
        <limit effort="1000.0" lower="-3.14" upper="3.14" velocity="0.5" />
        <origin rpy="0 0 0" xyz="0 0 0"/>
        <parent link="base_link"/>
        <child link="link_joint2"/>
        <!--dynamics damping="0.7"/-->
    </joint>


<link name="link_joint2">
    <collision>
         <origin xyz="0 0.005 1" rpy="0 3.1416 1.57"/>
      <geometry>
          <box size="0.01 0.01 0.01"/>
          <!--mesh filename="package://mrm_description/urdf/robot_arm_stl/zwerg.STL" scale="0.01 0.01 0.01"/-->
      </geometry>

    </collision>

    <visual>
      <!--origin xyz="0 0 0" rpy="0 0 -1.57"/-->
	  <origin xyz="-0.75 0 1.3" rpy="0 3.1416 1.57"/> 
      <geometry>
        <mesh filename="package://mrm_description/urdf/robot_arm_stl/Joint2Support.STL" scale="0.01 0.01 0.01"/>
      </geometry>
      <!--material name="blue"/-->
         <material name="grey">
             <color rgba="0.1 0.1 0.1 1.0"/>
           </material>
    </visual>

    <inertial>
      <mass value="0.01" />
      <origin xyz="-0.32 0.005 0.365" rpy="0 3.1416 1.57"/>
      <inertia ixx="0.4" ixy="0.0" ixz="0.0" iyy="0.4" iyz="0.0" izz="0.2" />
    </inertial>
</link>
    

<joint name="joint3" type="revolute">
        <axis xyz="1 0 0" />
        <limit effort="1000.0" lower="-3.14" upper="3.14" velocity="0.5" />
        <origin rpy="-1.57 0 0" xyz="0 0 1.3"/>
        <parent link="link_joint2"/>
        <child link="link_joint3"/>
        <!--dynamics damping="0.7"/-->
</joint>


<link name="link_joint3">
    

    <visual>
      <!--origin xyz="0 0 0" rpy="0 0 -1.57"/-->
	  <origin xyz="-1.1 0 0" rpy="0 3.1416 1.57"/> 
      <geometry>
        <mesh filename="package://mrm_description/urdf/robot_arm_stl/RohrHalterungJoint2_allinOne.STL" scale="0.01 0.01 0.01"/>
      </geometry>
      <!--material name="blue"/-->
         <material name="orange">
             <color rgba="0.1 0.1 0.1 1.0"/>
           </material>
    </visual>


    <collision>
         <origin xyz="0 0.005 1" rpy="0 3.1416 1.57"/>
      <geometry>
          <box size="0.01 0.01 0.01"/>
          <!--mesh filename="package://mrm_description/urdf/robot_arm_stl/zwerg.STL" scale="0.01 0.01 0.01"/-->
      </geometry>

    </collision>
    <inertial>
      <mass value="0.01" />
      <origin xyz="-0.32 0.005 0.365" rpy="0 3.1416 1.57"/>
      <inertia ixx="0.4" ixy="0.0" ixz="0.0" iyy="0.4" iyz="0.0" izz="0.2" />
    </inertial>
</link>    



<joint name="joint4" type="revolute">
        <axis xyz="0 0 1" />
        <limit effort="1000.0" lower="-3.14" upper="3.14" velocity="0.5" />
        <origin rpy="0 0 0" xyz="-1.3 0 -2.1"/>
        <parent link="link_joint3"/>
        <child link="link_joint4"/>
        <!--dynamics damping="0.7"/-->
</joint>


<link name="link_joint4">



    <visual>
      <geometry>
        <mesh filename="package://open_manipulator_support_description/meshes/link3.STL" scale="10 10 10"/>
      </geometry>
      <material name="grey"/>
    </visual>
    <collision>
      <geometry>
        <mesh filename="package://open_manipulator_support_description/meshes/link3.STL" scale="10 10 10"/>
      </geometry>
    </collision>

    <inertial>
      <mass value="${l3_mass}" />
      <origin xyz="${l3_cmx} ${l3_cmy} ${l3_cmz}"/>
      <inertia 
        ixx="${l3_ixx}"
        ixy="${l3_ixy}"
        ixz="${l3_ixz}"
        iyy="${l3_iyy}"
        iyz="${l3_iyz}"
        izz="${l3_izz}" />
    </inertial>
  </link>

<!--  Joint 3 -->
 
 <joint name="id_3" type="revolute">
    <parent link="link_joint4"/>
    <child link="link4"/>
    <origin xyz="0 0 -0.5" />
    <axis xyz="1 0 0"/>
    <limit velocity="2.9" effort="9.9" lower="-2.5" upper="2.5" />
  </joint>


<!--  Link 4 -->
  <link name="link4">
    <visual>
      <geometry>
        <mesh filename="package://open_manipulator_support_description/meshes/link4.STL" scale="10 10 10"/>
      </geometry>
      <material name="grey"/>
    </visual>

    <collision>
      <geometry>
        <mesh filename="package://open_manipulator_support_description/meshes/link4.STL" scale="10 10 10"/>
      </geometry>
    </collision>

    <inertial>
      <mass value="${l4_mass}" />
      <origin xyz="${l4_cmx} ${l4_cmy} ${l4_cmz}"/>
      <inertia 
        ixx="${l4_ixx}"
        ixy="${l4_ixy}"
        ixz="${l4_ixz}"
        iyy="${l4_iyy}"
        iyz="${l4_iyz}"
        izz="${l4_izz}" />
    </inertial>

  </link>



<!--  Joint 4-->
  <!--joint name="id_4" type="revolute">
    <parent link="link3"/>
    <child link="link4"/>
    <origin xyz="0 0 0.201"/>
    <axis xyz="0 0 1"/>
    <limit velocity="2.8" effort="3.1" lower="${-pi}" upper="${pi}" />
  </joint-->


<joint name="id_5" type="revolute">
    <parent link="link4"/>
    <child link="link5"/>
    <origin xyz="0 0 1"/>
    <axis xyz="1 0 0"/>
    <limit velocity="2.8" effort="3.1" lower="${-pi/2}" upper="2.2" />
  </joint>
  
  

<!--  Link 5 -->
  <link name="link5">
    <visual>
      <geometry>
        <mesh filename="package://open_manipulator_support_description/meshes/link5.STL" scale="10 10 10"/>
      </geometry>
      <material name="grey"/>
    </visual>

    <collision>
      <geometry>
        <mesh filename="package://open_manipulator_support_description/meshes/link5.STL" scale="10 10 10"/>
      </geometry>
    </collision>

    <inertial>
      <mass value="${l5_mass}" />
      <origin xyz="${l5_cmx} ${l5_cmy} ${l5_cmz}"/>
      <inertia
        ixx="${l5_ixx}"
        ixy="${l5_ixy}"
        ixz="${l5_ixz}"
        iyy="${l5_iyy}"
        iyz="${l5_iyz}"
        izz="${l5_izz}" />
    </inertial>
  </link>

<!--  Joint 5-->
  
  
<!--  Link 6 -->
  <link name="link6">
    <inertial>
      <mass value="${l6_mass}" />
      <origin xyz="${l6_cmx} ${l6_cmy} ${l6_cmz}"/>
      <inertia
        ixx="${l6_ixx}"
        ixy="${l6_ixy}"
        ixz="${l6_ixz}"
        iyy="${l6_iyy}"
        iyz="${l6_iyz}"
        izz="${l6_izz}" />
    </inertial>
    <visual>
      <geometry>
        <mesh filename="package://open_manipulator_support_description/meshes/link6.STL"  scale="10 10 10"/>
      </geometry>
      <material name="grey" />
    </visual>
    <collision>
      <geometry>
        <mesh filename="package://open_manipulator_support_description/meshes/link6.STL"  scale="10 10 10" />
      </geometry>
    </collision>
  </link>

<!--  Joint 6 -->
  <joint name="id_6" type="revolute">
    <origin xyz="0 0 1"/>
    <parent link="link5" />
    <child link="link6" />
    <axis xyz="0 0 1" />
	<limit velocity="2.8" effort="3.1" lower="${-pi}" upper="${pi}" />
  </joint>




 
<!-- Link 7-->
   <link name="link7">
    <inertial>
      <mass value="${l7_mass}" />
      <origin xyz="${l7_cmx} ${l7_cmy} ${l7_cmy} "/>
      <inertia
        ixx="${l7_ixx}"
        ixy="${l7_ixy}"
        ixz="${l7_ixz}"
        iyy="${l7_iyy}"
        iyz="${l7_iyz}"
        izz="${l7_izz}" />
    </inertial>
    <visual>
      <geometry>
        <mesh
          filename="package://open_manipulator_support_description/meshes/link7.STL" scale="10 10 10" />
      </geometry>
      <material name="grey" />
    </visual>
    <collision>
      <geometry>
        <mesh
          filename="package://open_manipulator_support_description/meshes/link7.STL" scale="10 10 10"/>
      </geometry>
    </collision>
  </link>

<!-- Joint 7 -->
	<joint
    name="id_7"
    type="revolute">
    <origin xyz="0 0 0.039" />
    <parent link="link6" />
    <child link="link7" />
    <axis xyz="0 0 1" />
    <limit velocity="2.8" effort="3.1" lower="${-pi}" upper="${pi}" />
  </joint>

  <!-- Transmission 7 --> 
  <!--transmission name="tran7">
    <type>transmission_interface/SimpleTransmission</type>
    <joint name="id_7">
      <hardwareInterface>hardware_interface/EffortJointInterface</hardwareInterface>
    </joint>
    <actuator name="motor7">
      <hardwareInterface>hardware_interface/EffortJointInterface</hardwareInterface>
      <mechanicalReduction>1</mechanicalReduction>
    </actuator>
  </transmission-->

  <!--  Gripper Left--> 
  
<link name="gripper_l">
    <inertial>
      <mass value="${g_mass}" />
      <origin xyz="${g_cmx} ${g_cmy} ${g_cmz}"/>
      <inertia
        ixx="${g_ixx}"
        ixy="${g_ixy}"
        ixz="${g_ixz}"
        iyy="${g_iyy}"
        iyz="${g_iyz}"
        izz="${g_izz}" />
    </inertial>
    
    <visual>
      <geometry>
        <mesh
          filename="package://open_manipulator_support_description/meshes/gripper.STL"  scale="10 10 10"/>
      </geometry>
      <material name="grey" />
    </visual>
    
   <collision>
      <geometry>
        <mesh
          filename="package://open_manipulator_support_description/meshes/gripper.STL" scale="10 10 10"/>
      </geometry>
    </collision> 
  </link>

<!--Gripper Left Joint -->
  <joint name="joint8" type="prismatic">
    <origin xyz="-0.015 0 0.0595" rpy="0 0 ${pi}"/>
    <parent link="link6" />
    <child link="gripper_l" />
    <axis xyz="1 0 0" />
    <limit velocity="0.1" effort=".1" lower="-.033" upper="0"/>
    <mimic joint="id_7" multiplier="-0.01" offset="-0.0110133334" /> 
  </joint> 


<!--  Gripper Right --> 
   <link name="gripper_r">
    <inertial>
      <mass value="${g_mass}" />
      <origin xyz="${-g_cmx} ${g_cmy} ${g_cmz}"/>
      <inertia
        ixx="${g_ixx}"
        ixy="${g_ixy}"
        ixz="${g_ixz}"
        iyy="${g_iyy}"
        iyz="${g_iyz}"
        izz="${g_izz}" />
    </inertial>
        <visual>
      <geometry>
        <mesh filename="package://open_manipulator_support_description/meshes/gripper.STL"  scale="10 10 10"/>
      </geometry>
      <material name="grey" />
    </visual>
    
    <collision>
      <geometry>
        <mesh filename="package://open_manipulator_support_description/meshes/gripper.STL"  scale="10 10 10"/>
      </geometry>
    </collision> 
  </link>
  
<!--Gripper Right Joint -->
   <joint name="joint9" type="prismatic">
    <origin xyz="0.015 0 0.0595" />
    <parent link="link6" />
    <child link="gripper_r" />
    <axis xyz="1 0 0" />
        <limit velocity="0.1" effort=".1" lower="0" upper=".033"/>
    <mimic joint="joint8" multiplier="1" offset="0" />
  </joint>

</robot>
