<?xml version="1.0" ?>

<robot name="simple_example" xmlns:xacro="http://www.ros.org/wiki/xacro">

<xacro:include filename="$(find mrm_description)/urdf/materials.xacro" />

<link name="world"/>

<joint name="fixed" type="fixed">
  <parent link="world"/>
  <child link="base_link"/>
</joint>

  <link name="base_link">
    <collision>
      <origin xyz="0 0 0.75" rpy="-3.1416 0 0"/>
      <geometry>
    <box size="0.01 0.01 0.01"/>
         <!--mesh filename="package://mrm_description/urdf/robot_arm_stl/basecone.STL" scale="0.01 0.01 0.01"/-->
      </geometry>
    </collision>

    <visual>
      <origin xyz="0 0 0.75" rpy="-3.1416 0 0"/>
      <geometry>
        <mesh filename="package://mrm_description/urdf/robot_arm_stl/basecone.STL" scale="0.01 0.01 0.01"/>
      </geometry>
    </visual>

    <inertial>
      <mass value="10" />
      <origin xyz="0 0 0.75" rpy="-3.1416 0 0"/>
      <inertia ixx="0.4" ixy="0.0" ixz="0.0" iyy="0.4" iyz="0.0" izz="0.2" />
    </inertial>
  </link>

    <!--joint name="joint1" type="revolute">
        <axis xyz="0 0 1" />
        <limit effort="1000.0" lower="-3.14" upper="3.14" velocity="0.5" />
        <origin rpy="0 0 0" xyz="0 0 0.5"/>
        <parent link="base_link"/>
        <child link="link1"/>
    </joint-->
    <joint name="joint1" type="revolute">
        <axis xyz="0 0 1" />
        <limit effort="1000.0" lower="-3.14" upper="3.14" velocity="0.5" />
        <origin rpy="0 0 0" xyz="0 0 0.8"/>
        <parent link="base_link"/>
        <child link="link1"/>
        <!--dynamics damping="0.7"/-->
    </joint>



    <link name="link1">
        <visual>
            <origin rpy="0 0 0" xyz="0 0 0"/>
            <geometry>
                <cylinder radius="0.43" length="0.3"/>
            </geometry>
              <material name="orange">
                <color rgba="1.0 0.42 0.04 1.0"/>
              </material>
            <!--material name="orange"/-->
        </visual>

        <collision>
          <origin rpy="0 0 0" xyz="0 0 0"/>
            <geometry>
                <!--cylinder radius="0.01" length="0.01"/-->
                <cylinder radius="0.43" length="0.3"/>
            </geometry>
        </collision>

        <inertial>
            <mass value="2.0" />
            <origin rpy="0 0 0" xyz="0 0 0"/>
            <inertia ixx="0.4" ixy="0.0" ixz="0.0" iyy="0.4" iyz="0.0" izz="0.2" />
        </inertial>
    </link>

    <joint name="joint2" type="fixed">
        <axis xyz="0 0 0" />
        <!--limit effort="1000.0" lower="-3.14" upper="3.14" velocity="0.5" /-->
        <origin rpy="0 0 0" xyz="0 0 0.15"/>
        <parent link="link1"/>
        <child link="halter1"/>
    </joint>

  <link name="halter1">
    <collision>
      <origin xyz="-0.55 -0.25 0.0" rpy="0 0 0"/>
      <geometry>
          <!--box size="0.01 0.01 0.01"/-->
          <mesh filename="package://mrm_description/urdf/robot_arm_stl/shoulderplate.STL" scale="0.01 0.01 0.01"/>
      </geometry>

    </collision>

    <visual>
      <origin xyz="-0.55 -0.25 0.0" rpy="0 0 0"/>
      <geometry>
        <mesh filename="package://mrm_description/urdf/robot_arm_stl/shoulderplate.STL" scale="0.01 0.01 0.01"/>
      </geometry>
            <material name="grey">
             <color rgba="0.1 0.1 0.1 1.0"/>
            </material>
      <!--material name="white"/-->
    </visual>

    <inertial>
      <mass value="0.01" />
      <origin xyz="-0.55 -0.25 0.0" rpy="0 0 0"/>
      <inertia ixx="0.4" ixy="0.0" ixz="0.0" iyy="0.4" iyz="0.0" izz="0.2" />
    </inertial>
  </link>


  <joint name="halter1_holderjoint2" type="fixed">
        <axis xyz="0 0 1" />
        <!--limit effort="1000.0" lower="-3.14" upper="3.14" velocity="0.5" /-->
        <origin rpy="0 0 0" xyz="-0.4 0 0.1"/>
        <parent link="halter1"/>
        <child link="holderjoint2"/>
  </joint>

 <link name="holderjoint2">
    <collision>
         <origin xyz="-0.32 0.005 1" rpy="0 3.1416 1.57"/>
      <geometry>
          <box size="0.01 0.01 0.01"/>
          <!--mesh filename="package://mrm_description/urdf/robot_arm_stl/zwerg.STL" scale="0.01 0.01 0.01"/-->
      </geometry>

    </collision>

    <visual>
      <!--origin xyz="0 0 0" rpy="0 0 -1.57"/-->
	  <origin xyz="-0.32 0.005 0.365" rpy="0 3.1416 1.57"/>
      <geometry>
        <mesh filename="package://mrm_description/urdf/robot_arm_stl/Joint2Support.STL" scale="0.01 0.01 0.01"/>
      </geometry>
      <!--material name="blue"/-->
         <material name="grey">
             <color rgba="0.1 0.1 0.1 1.0"/>
           </material>
    </visual>

    <inertial>
      <mass value="0.01" />
      <origin xyz="-0.32 0.005 0.365" rpy="0 3.1416 1.57"/>
      <inertia ixx="0.4" ixy="0.0" ixz="0.0" iyy="0.4" iyz="0.0" izz="0.2" />
    </inertial>
  </link>
    


<joint name="joint11" type="revolute">
        <axis xyz="1 0 0" />
        <limit effort="1000.0" lower="-3.14" upper="3.14" velocity="0.5" />
        <origin rpy="0 0 0" xyz="0 0.005 0.365"/>
        <parent link="holderjoint2"/>
        <child link="link2"/>
        <!--dynamics damping="0.7"/-->
</joint>



    <link name="link2">
        <visual>
            <origin rpy="0 1.57 0" xyz="-0.42 0 0"/>
            <geometry>
                <cylinder radius="0.3" length="0.2"/>
            </geometry>
              <material name="orange">
                <color rgba="1.0 0.42 0.04 1.0"/>
              </material>
            <!--material name="orange"/-->
        </visual>

        <collision>
          <origin rpy="0 1.57  0" xyz="0 0 0"/>
            <geometry>
                <!--cylinder radius="0.01" length="0.01"/-->
                <cylinder radius="0.1" length="0.1"/>
            </geometry>
        </collision>

        <inertial>
            <mass value="2.0" />
            <origin rpy="0 0 0" xyz="0 0 0"/>
            <inertia ixx="0.4" ixy="0.0" ixz="0.0" iyy="0.4" iyz="0.0" izz="0.2" />
        </inertial>
    </link>




<joint name="link2_LinkRohr1" type="fixed">
        <axis xyz="0 0 1" />
        <!--limit effort="1000.0" lower="-3.14" upper="3.14" velocity="0.5" /-->
        <origin rpy="0 0 0" xyz="-0.2 0 0.05"/>
        <parent link="link2"/>
        <child link="LinkRohr1"/>
 </joint>


 <link name="LinkRohr1">
    <collision>
         <origin xyz="-0.32 0.005 1" rpy="0 0 1.57"/>
      <geometry>
          <box size="0.01 0.01 0.01"/>
      </geometry>

    </collision>

    <visual>
      <!--origin xyz="0 0 0" rpy="0 0 -1.57"/-->
	  <origin xyz="-0.32 0.00 -0.05" rpy="0 -1.57 1.57"/>
      <geometry>
        <mesh filename="package://mrm_description/urdf/robot_arm_stl/RohrHalterungJoint2.STL" scale="0.01 0.01 0.01"/>
      </geometry>
      <!--material name="blue"/-->
         <material name="green">
             <color rgba="1 1 1 1"/>
         </material>
    </visual>

    <inertial>
      <mass value="0.01" />
      <origin xyz="-0.32 0.005 0.365" rpy="0 3.1416 1.57"/>
      <inertia ixx="0.4" ixy="0.0" ixz="0.0" iyy="0.4" iyz="0.0" izz="0.2" />
    </inertial>
  </link>








<joint name="LinkRohr1_Rohr1" type="fixed">
        <axis xyz="0 0 0" />
        <!--limit effort="1000.0" lower="-3.14" upper="3.14" velocity="0.5" /-->
        <origin rpy="0 0 0" xyz="0 0 0"/>
        <parent link="LinkRohr1"/>
        <child link="Rohr1"/>
 </joint>



    <link name="Rohr1">
        <visual>
            <origin rpy="1.57 0 0" xyz="-0.5 -0.8 -0.04"/>
            <geometry>
                <cylinder radius="0.11" length="1.5"/>
            </geometry>
              <material name="blue">
                <color rgba="1.0 0.42 0.04 1.0"/>
              </material>
            <!--material name="orange"/-->
        </visual>

        <collision>
          <origin rpy="1.57 0 0" xyz="-0.5 -0.8 -0.04"/>
            <geometry>
                <cylinder radius="0.01" length="1.5"/>
            </geometry>
        </collision>

        <inertial>
            <mass value="2.0" />
            <origin rpy="0 0 0" xyz="0 0 0"/>
            <inertia ixx="0.4" ixy="0.0" ixz="0.0" iyy="0.4" iyz="0.0" izz="0.2" />
        </inertial>
    </link>


<joint name="joint111" type="revolute">
        <axis xyz="0 0 1" />
        <limit effort="1000.0" lower="-3.14" upper="3.14" velocity="0.5" />
        <origin rpy="1.57 0 0" xyz="-0.5 -1.65 -0.05"/>
        <parent link="Rohr1"/>
        <child link="link3"/>
        <!--dynamics damping="0.7"/-->
</joint>



    <link name="link3">
        <visual>
            <origin rpy="0 0 0" xyz="0 0 0"/>
            <geometry>
                <cylinder radius="0.1" length="0.2"/>
            </geometry>
              <material name="orange">
                <color rgba="1.0 0.42 0.04 1.0"/>
              </material>
            <!--material name="orange"/-->
        </visual>

        <collision>
          <origin rpy="0 0 0" xyz="0 0 1"/>
            <geometry>
                <!--cylinder radius="0.01" length="0.01"/-->
                <cylinder radius="0.05" length="0.05"/>
            </geometry>
        </collision>

        <inertial>
            <mass value="2.0" />
            <origin rpy="0 0 0" xyz="0 0 0"/>
            <inertia ixx="0.4" ixy="0.0" ixz="0.0" iyy="0.4" iyz="0.0" izz="0.2" />
        </inertial>
    </link>




<gazebo>
    <plugin name="gazebo_ros_control" filename="libgazebo_ros_control.so">
      <robotNamespace></robotNamespace>
      <controlPeriod>0.001</controlPeriod>
      <robotSimType>gazebo_ros_control/DefaultRobotHWSim</robotSimType>
    </plugin>
</gazebo>


   <!-- ROS Control plugin for Gazebo -->
   <!--gazebo>
    <plugin name="gazebo_ros_control" filename="libgazebo_ros_control.so">
	  
      <robotNamespace>/simple_model</robotNamespace>
      
      <robotSimType>gazebo_ros_control/DefaultRobotHWSim</robotSimType>
      <legacyModeNS>true</legacyModeNS>
    </plugin>
  </gazebo-->

   <!-- Link1 -->
  <gazebo reference="base_link">
    <material>Gazebo/Red</material>
  </gazebo>

  <!-- Link2 -->
  <gazebo reference="link1">
    <mu1>0.2</mu1>
    <mu2>0.2</mu2>
    <material>Gazebo/Orange</material>
  </gazebo>

  <!-- Link3 -->
  <gazebo reference="halter1">
    <mu1>0.2</mu1>
    <mu2>0.2</mu2>
    <material>Gazebo/Black</material>
  </gazebo>


 <gazebo reference="holderjoint2">
    <mu1>0.2</mu1>
    <mu2>0.2</mu2>
    <material>Gazebo/Orange</material>
  </gazebo>

<gazebo reference="link11">
    <mu1>0.2</mu1>
    <mu2>0.2</mu2>
    <material>Gazebo/Orange</material>
  </gazebo>

  <!-- camera_link -->
  <gazebo reference="LinkRohr1">
    <mu1>0.2</mu1>
    <mu2>0.2</mu2>
    <material>Gazebo/Blue</material>
  </gazebo>






<transmission name="tran1">
    <type>transmission_interface/SimpleTransmission</type>
    <actuator name="motor1">
      <mechanicalReduction>1</mechanicalReduction>
    </actuator>
    <joint name="joint1">
      
      <!--hardwareInterface>hardware_interface/VelocityJointInterface</hardwareInterface-->
     <hardwareInterface>hardware_interface/PositionJointInterface</hardwareInterface>
    </joint>
</transmission>

<transmission name="tran2">
    <type>transmission_interface/SimpleTransmission</type>
    <actuator name="motor2">
      <mechanicalReduction>1</mechanicalReduction>
    </actuator>
    <joint name="joint11">
      
      <!--hardwareInterface>hardware_interface/VelocityJointInterface</hardwareInterface-->
     <hardwareInterface>hardware_interface/PositionJointInterface</hardwareInterface>
    </joint>
</transmission>



</robot>
